terminate called after throwing an instance of 'std::out_of_range'
  what():  stoi
Przerwane (zrzut pamiÄ™ci)
